<?xml version="1.0" ?>
<robot name="simple_four_wheel_car">
  <!-- Base Link -->
  <link name="base_link">
    <visual>
      <origin xyz="0 0 0" rpy="0 0 0"/>
      <geometry>
        <box size="0.20 0.20 0.05"/>
      </geometry>
      <material name="blue">
        <color rgba="0 0 1 1"/>
      </material>
    </visual>
    <collision>
      <origin xyz="0 0 0" rpy="0 0 0"/>
      <geometry>
        <box size="0.2 0.2 0.05"/>
      </geometry>
    </collision>
    <inertial>
        <origin xyz="0.0 0 0" rpy="0 0 0"/>
        <mass value="0.4"/>
        <inertia ixx="0.0000" 
                 ixy="0" ixz="0"
                 iyx="0" iyy="0.0000"
                 iyz="0"
                 izx="0" izy="0" izz="0.0000"/>
    </inertial>
  </link>

  <!-- Left Wheel Link -->
  <link name="left_wheel_link">
    <visual>
      <origin xyz="0 0 0" rpy="1.5708 0 0"/>
      <geometry>
        <cylinder length="0.025" radius="0.025"/>
      </geometry>
      <material name="black">
        <color rgba="0 0 0 1"/>
      </material>
    </visual>
    <collision>
      <origin xyz="0 0 0" rpy="1.5708 0 0"/>
      <geometry>
        <cylinder length="0.025" radius="0.025"/>
      </geometry>
    </collision>
    <inertial>
        <origin xyz="0 0 0" rpy="0 0 0"/>
        <mass value="0.05"/>
        <inertia ixx="0.0000" 
                 ixy="0" ixz="0"
                 iyx="0" iyy="0.0000" 
                 iyz="0"
                 izx="0" izy="0" izz="0.0000"/>
    </inertial>
  </link>

  <!-- Joint: Base Link to Left Wheel -->
  <joint name="left_wheel_joint" type="continuous">
    <parent link="base_link"/>
    <child link="left_wheel_link"/>
    <origin xyz="-0.05 -0.11 -0.025" rpy="0 0 0"/>
    <axis xyz="0 1 0"/>
  </joint>

  <!-- Right Wheel Link -->
  <link name="right_wheel_link">
    <visual>
      <origin xyz="0 0 0" rpy="1.5708 0 0"/>
      <geometry>
        <cylinder length="0.025" radius="0.025"/>
      </geometry>
      <material name="black">
        <color rgba="0 0 0 1"/>
      </material>
    </visual>
    <collision>
      <origin xyz="0 0 0" rpy="1.5708 0 0"/>
      <geometry>
        <cylinder length="0.025" radius="0.025"/>
      </geometry>
    </collision>
    <inertial>
        <origin xyz="0 0 0" rpy="0 0 0"/>
        <mass value="0.05"/>
        <inertia ixx="0.0000" 
                 ixy="0" ixz="0"
                 iyx="0" iyy="0.0000" 
                 iyz="0"
                 izx="0" izy="0" izz="0.0000"/>
    </inertial>
  </link>

  <!-- Joint: Base Link to Right Wheel -->
  <joint name="right_wheel_joint" type="continuous">
    <parent link="base_link"/>
    <child link="right_wheel_link"/>
    <origin xyz="-0.05 0.11 -0.025" rpy="0 0 0"/>
    <axis xyz="0 1 0"/>
  </joint>

  <!-- Front Caster -->
  <link name="front_caster_link">
    <visual>
      <origin xyz="0 0 0" rpy="0 0 0"/>
      <geometry>
        <sphere radius="0.0175"/>
      </geometry>
      <material name="black">
        <color rgba="0 0 0 1"/>
      </material>
    </visual>
    <collision>
      <origin xyz="0 0 0" rpy="0 0 0"/>
      <geometry>
        <sphere radius="0.0175"/>
      </geometry>
    </collision>
    <inertial>
        <origin xyz="0 0 0" rpy="0 0 0"/>
        <mass value="0.001"/>
        <inertia ixx="0.00000"
                 ixy="0" ixz="0"
                 iyx="0" iyy="0.00000" 
                 iyz="0"
                 izx="0" izy="0" izz="0.0000"/>
    </inertial>
  </link>

  <!-- Front Caster Joint -->
  <joint name="front_caster_joint" type="fixed">
    <parent link="base_link"/>
    <child link="front_caster_link"/>
    <origin xyz="0.075 0.0 -0.032" rpy="0 0 0"/>
    <axis xyz="0 0 1"/>
  </joint>

  <!-- Bottom Sensor -->
  <link name="bottom_sensor_link">
    <visual>
      <origin xyz="0 0 0" rpy="0 0 0"/>
      <geometry>
        <box size="0.01 0.01 0.01"/>
      </geometry>
      <material name="black">
        <color rgba="0 0 0 1"/>
      </material>
    </visual>
    <collision>
      <origin xyz="0 0 0" rpy="0 0 0"/>
      <geometry>
        <box size="0.01 0.01 0.01"/>
      </geometry>
    </collision>
    <inertial>
        <origin xyz="0 0 0" rpy="0 0 0"/>
        <mass value="0.001"/>
        <inertia ixx="0.00000"
                 ixy="0" ixz="0"
                 iyx="0" iyy="0.00000"
                 iyz="0"
                 izx="0" izy="0" izz="0.00000"/>
    </inertial>
  </link>

  <!-- Bottom Sensor Joint -->
  <joint name="bottom_sensor_joint" type="fixed">
    <parent link="base_link"/>
    <child link="bottom_sensor_link"/>
    <origin xyz="0.09 0.0 -0.025" rpy="0 0 0"/>
    <axis xyz="0 0 1"/>
  </joint>

  <link name="b_target_position_vertual_link">
    <inertial>
        <origin xyz="0 0 0" rpy="0 0 0" />
        <mass value="0.001" />
        <inertia ixx="0.00000" 
            ixy="0"  ixz="0"
            iyx="0"  iyy="0.0000" 
            iyz="0"
            izx="0"  izy="0"  izz="0.0000" />
    </inertial>
  </link>

  <joint name="bottom_sensor_target_joint" type="fixed">
    <parent link="bottom_sensor_link"/>
    <child link="b_target_position_vertual_link"/>
    <origin xyz="0.0 0.0 -0.05" rpy="0 0 0"/>
    <axis xyz="0 0 1"/>
  </joint>

</robot>
