<?xml version="1.0"?>
<robot name="Self_Balancing_Robot">
  <!-- Chassis -->
  <link name="Chassis">
    <visual>
      <geometry>
        <box size="0.12 0.08 0.14"/> <!-- Length: 10 cm, Width: 10 cm, Height: 13 cm -->
      </geometry>
      <origin xyz="0 0 0" rpy="0 0 1.5708"/> 
      <material name="ChassisMaterial">
        <color rgba="0.75 0.75 0.75 1"/>  <!-- Grey color for chassis -->
      </material>
    </visual>
    <collision>
      <geometry>
        <box size="0.12 0.08 0.14"/> <!-- Length: 10 cm, Width: 10 cm, Height: 13 cm -->
      </geometry>
      <origin xyz="0 0 0" rpy="0 0 1.5708"/> 
    </collision>
    <inertial>
      <origin xyz="0 0 0.011" rpy="0 0 1.5708"/>
      <mass value="0.478"/>
      <inertia ixx="0.025" ixy="0" ixz="0" iyy="0.0013" iyz="0" izz="0.025"/>
    </inertial>
  </link>

  <!-- Left Wheel -->
  <link name="Left_Wheel">
    <visual>
      <geometry>
        <cylinder radius="0.045" length="0.006"/> <!-- Diameter: 9 cm, Width: 3 cm -->
      </geometry>
      <origin xyz="0 0.073 0" rpy="1.5708 0 0 "/> 
      <material name="WheelMaterial">
        <color rgba="1 0 0 1"/>  <!-- Red color for left wheel -->
      </material>
    </visual>
    <collision>
      <geometry>
        <cylinder radius="0.045" length="0.006"/> <!-- Diameter: 9 cm, Width: 3 cm -->
      </geometry>
      <origin xyz="0 0.073 0" rpy="1.5708 0 0 "/> 
    </collision>
    <inertial>
      <origin xyz="0 0.073 0" rpy="1.5708 0 0 "/>
      <mass value="0.015"/>
      <inertia ixx="0.00" ixy="0" ixz="0" iyy="0.000" iyz="0" izz="0.00"/>
    </inertial>
  </link>

  <!-- Right Wheel -->
  <link name="Right_Wheel">
    <visual>
      <geometry>
        <cylinder radius="0.045" length="0.006"/> <!-- Diameter: 9 cm, Width: 3 cm -->
      </geometry>
      <origin xyz="0 -0.073 0" rpy="-1.5708 0 0 "/>  
      <material name="Wheel_R_Material">
        <color rgba="1 1 1 1"/>  <!-- White color for right wheel -->
      </material>
    </visual>
    <collision>
      <geometry>
        <cylinder radius="0.045" length="0.006"/> <!-- Diameter: 9 cm, Width: 3 cm -->
      </geometry>
      <origin xyz="0 -0.073 0" rpy="-1.5708 0 0 "/> 
    </collision>
    <inertial>
      <origin xyz="0 -0.073 0" rpy="-1.5708 0 0 "/>
      <mass value="0.015"/>
      <inertia ixx="0.00" ixy="0" ixz="0" iyy="0.00" iyz="0" izz="0.00"/>
    </inertial>
  </link>

  <!-- Left Wheel Joint -->
  <joint name="left_wheel_joint" type="continuous">
    <parent link="Chassis"/>
    <child link="Left_Wheel"/>
    <origin xyz="0 0.0 -0.05" rpy="0 0 0"/>
    <limit effort="0.01" velocity="1000"/> <!-- effort = force -->
    <axis xyz="0 1 0"/>
  </joint>

  <!-- Right Wheel Joint -->
  <joint name="right_wheel_joint" type="continuous">
    <parent link="Chassis"/>
    <child link="Right_Wheel"/>
    <origin xyz="0 0.0 -0.05" rpy="0 0 0"/>
    <limit effort="0.01" velocity="1000"/> <!-- effort = force -->
    <axis xyz="0 1 0"/>
  </joint>

</robot>
