<?xml version="1.0"?>
<robot name="Self_Balancing_Robot">
  <!-- Chassis -->
  <link name="Chassis">
    <visual>
      <geometry>
        <mesh filename="meshes/Robot_V1.dae" />
      </geometry>
      <origin xyz="0 0 0.0" rpy="0 0 0 "/> 
      <material name="ChassisMaterial">
        <color rgba="0.75 0.75 0.75 1"/>  <!-- Warna abu-abu untuk chassis -->
      </material>
    </visual>
    <collision>
      <geometry>
        <mesh filename="meshes/Robot_V1.dae" />
      </geometry>
      <origin xyz="0 0 0.0" rpy="0 0 0"/> 
    </collision>
    <inertial>
      <origin xyz="0 0 0.065" rpy="0 0 0"/>
      <mass value="0.450"/>
      <inertia ixx="0.00" ixy="0" ixz="0" iyy="0.00" iyz="0" izz="0.00"/>
    </inertial>
  </link>

  <!-- Left Wheel -->
  <link name="Left_Wheel">
    <visual>
      <geometry>
        <mesh filename="meshes/Robot_Wheel_Left.dae"  />
      </geometry>
      <origin xyz="0 0.0 -0.044" rpy="0 0 0"/>
      <material name="WheelMaterial">
        <color rgba="1 0 0 1"/>  <!-- Warna merah untuk roda Kiri -->
      </material>
    </visual>
    <collision>
      <geometry>
        <mesh filename="meshes/Robot_Wheel_Left.dae"  />
      </geometry>
      <origin xyz="0 0.0 -0.044" rpy="0 0 0"/> 
    </collision>
    <inertial>
      <origin xyz="0 0.0 -0.044" rpy="0 0 0"/>
      <mass value="0.015"/>
      <inertia ixx="0.00" ixy="0" ixz="0" iyy="0.000" iyz="0" izz="0.00"/>
    </inertial>
  </link>

  <!-- Right Wheel -->
  <link name="Right_Wheel">
    <visual>
      <geometry>
        <mesh filename="meshes/Robot_Wheel_Right.dae" />
      </geometry>
      <origin xyz="0 0.0 -0.044" rpy="0 0 0"/>  
      <material name="Wheel_R_Material">
        <color rgba="1 1 1 1"/>  <!-- Warna putih untuk roda Kanan-->
      </material>
    </visual>
    <collision>
      <geometry>
        <mesh filename="meshes/Robot_Wheel_Right.dae" />
      </geometry>
      <origin xyz="0 0.0 -0.044" rpy="0 0 0"/> 
    </collision>
    <inertial>
      <origin xyz="0 0.0 -0.044" rpy="0 0 0"/>
      <mass value="0.015"/>
      <inertia ixx="0.000" ixy="0" ixz="00" iyy="0.000" iyz="0" izz="0.000"/>
    </inertial>
  </link>

  <!-- Left Wheel Joint -->
  <joint name="left_wheel_joint" type="continuous">
    <parent link="Chassis"/>
    <child link="Left_Wheel"/>
    <origin xyz="0.0 0.00 0.044" rpy="0 0 0"/>
    <limit effort="0.055" velocity="1000"/> <!--effort = force-->
    <axis xyz="0 1 0"/>
  </joint>

  <!-- Right Wheel Joint -->
  <joint name="right_wheel_joint" type="continuous">
    <parent link="Chassis"/>
    <child link="Right_Wheel"/>
    <origin xyz="0.0 0.00 0.044" rpy="0 0 0"/>
    <limit effort="0.055" velocity="1000"/> <!--efort = force-->
    <axis xyz="0 1 0"/>
  </joint>

  <link name="line_sensor_link">
    <visual>
      <origin xyz="0 0 0" rpy="0 0 0 "/>
      <geometry>
        <box size="0.01 0.01 0.01"/>
      </geometry>
      <material name="black">
        <color rgba="0 0 0 1"/>
      </material>
    </visual>
    <collision>
      <origin xyz="0 0 0" rpy="0 0 0 "/>
      <geometry>
        <box size="0.01 0.01 0.01"/>
      </geometry>
    </collision>
    <inertial>
        <origin xyz="0 0 0" rpy="0 0 0" />
        <mass value="0.0001" />
        <inertia ixx="0.00000" 
            ixy="0"  ixz="0"
            iyx="0"  iyy="0.00000" 
            iyz="0"
            izx="0"  izy="0"  izz="0.00000" />
    </inertial>
  </link>

  <joint name="line_sensor_joint" type="fixed">
    <parent link="Chassis"/>
    <child link="line_sensor_link"/>
    <origin xyz="0.00 0.0 0.01" rpy="0 0 0"/>
    <axis xyz="0 0 1"/>
  </joint>

  <link name="line_target_position_vertual_link">
        <inertial>
        <origin xyz="0 0 0" rpy="0 0 0" />
        <mass value="0.0001" />
        <inertia ixx="0.00000" 
            ixy="0"  ixz="0"
            iyx="0"  iyy="0.00000" 
            iyz="0"
            izx="0"  izy="0"  izz="0.00000" />
    </inertial>
  </link>

  <joint name="line_sensor_target_joint" type="fixed">
    <parent link="line_sensor_link"/>
    <child link="line_target_position_vertual_link"/>
    <origin xyz="0.0 0.0 -0.001" rpy="0 0 0"/>
    <axis xyz="0 0 1"/>
  </joint>
</robot>
