<?xml version="1.0"?>
<robot name="self_balancing_robot">
    <!-- Materials -->
    <material name="blue">
        <color rgba="0 0 0.8 1"/>
    </material>
    <material name="black">
        <color rgba="0 0 0 1"/>
    </material>
    <material name="white">
        <color rgba="1 1 1 1"/>
    </material>

    <!-- Base Properties -->
    <link name="base_link">
        <visual>
            <origin xyz="0 0 0" rpy="0 0 0"/>
            <geometry>
                <box size="0.08 0.15 0.20"/>
            </geometry>
            <material name="blue"/>
        </visual>
        <collision>
            <origin xyz="0 0 0" rpy="0 0 0"/>
            <geometry>
                <box size="0.08 0.15 0.20"/>
            </geometry>
        </collision>
        <inertial>
            <origin xyz="0 0 0" rpy="0 0 0"/>
            <mass value="1.0"/>
            <inertia ixx="0.0016" ixy="0" ixz="0" iyy="0.0023" iyz="0" izz="0.0036"/>
        </inertial>
        <contact>
            <lateral_friction value="1.0"/>
            <rolling_friction value="0.1"/>
            <spinning_friction value="0.5"/>
        </contact>
    </link>

    <!-- Left Wheel -->
    <link name="left_wheel">
        <visual>
            <origin xyz="0 0 0" rpy="1.5708 0 0"/>
            <geometry>
                <cylinder length="0.02" radius="0.05"/>
            </geometry>
            <material name="black"/>
        </visual>
        <collision>
            <origin xyz="0 0 0" rpy="1.5708 0 0"/>
            <geometry>
                <cylinder length="0.02" radius="0.05"/>
            </geometry>
        </collision>
        <inertial>
            <origin xyz="0 0 0" rpy="1.5708 0 0"/>
            <mass value="0.2"/>
            <inertia ixx="0.00012" ixy="0" ixz="0" iyy="0.00012" iyz="0" izz="0.00025"/>
        </inertial>
        <contact>
            <lateral_friction value="2.0"/>
            <rolling_friction value="0.1"/>
            <spinning_friction value="0.1"/>
        </contact>
    </link>

    <joint name="left_wheel_joint" type="continuous">
        <parent link="base_link"/>
        <child link="left_wheel"/>
        <origin xyz="0 0.085 -0.085" rpy="0 0 0"/>
        <axis xyz="0 1 0"/>
        <dynamics damping="0.1" friction="0.1"/>
        <limit effort="5.0" velocity="10.0"/>
    </joint>

    <!-- Right Wheel -->
    <link name="right_wheel">
        <visual>
            <origin xyz="0 0 0" rpy="1.5708 0 0"/>
            <geometry>
                <cylinder length="0.02" radius="0.05"/>
            </geometry>
            <material name="black"/>
        </visual>
        <collision>
            <origin xyz="0 0 0" rpy="1.5708 0 0"/>
            <geometry>
                <cylinder length="0.02" radius="0.05"/>
            </geometry>
        </collision>
        <inertial>
            <origin xyz="0 0 0" rpy="1.5708 0 0"/>
            <mass value="0.2"/>
            <inertia ixx="0.00012" ixy="0" ixz="0" iyy="0.00012" iyz="0" izz="0.00025"/>
        </inertial>
        <contact>
            <lateral_friction value="2.0"/>
            <rolling_friction value="0.1"/>
            <spinning_friction value="0.1"/>
        </contact>
    </link>

    <joint name="right_wheel_joint" type="continuous">
        <parent link="base_link"/>
        <child link="right_wheel"/>
        <origin xyz="0 -0.085 -0.085" rpy="0 0 0"/>
        <axis xyz="0 1 0"/>
        <dynamics damping="0.1" friction="0.1"/>
        <limit effort="5.0" velocity="10.0"/>
    </joint>

    <!-- IMU Sensor -->
    <link name="imu_link">
        <visual>
            <origin xyz="0 0 0" rpy="0 0 0"/>
            <geometry>
                <box size="0.02 0.02 0.01"/>
            </geometry>
            <material name="white"/>
        </visual>
        <collision>
            <origin xyz="0 0 0" rpy="0 0 0"/>
            <geometry>
                <box size="0.02 0.02 0.01"/>
            </geometry>
        </collision>
        <inertial>
            <origin xyz="0 0 0" rpy="0 0 0"/>
            <mass value="0.01"/>
            <inertia ixx="0.000001" ixy="0" ixz="0" iyy="0.000001" iyz="0" izz="0.000001"/>
        </inertial>
    </link>

    <joint name="imu_joint" type="fixed">
        <parent link="base_link"/>
        <child link="imu_link"/>
        <origin xyz="0 0 0.04" rpy="0 0 0"/>
    </joint>

    <!-- MCU Board -->
    <link name="mcu_link">
        <visual>
            <origin xyz="0 0 0" rpy="0 0 0"/>
            <geometry>
                <box size="0.07 0.05 0.01"/>
            </geometry>
            <material name="black"/>
        </visual>
        <collision>
            <origin xyz="0 0 0" rpy="0 0 0"/>
            <geometry>
                <box size="0.07 0.05 0.01"/>
            </geometry>
        </collision>
        <inertial>
            <origin xyz="0 0 0" rpy="0 0 0"/>
            <mass value="0.05"/>
            <inertia ixx="0.000004" ixy="0" ixz="0" iyy="0.000004" iyz="0" izz="0.000007"/>
        </inertial>
    </link>

    <joint name="mcu_joint" type="fixed">
        <parent link="base_link"/>
        <child link="mcu_link"/>
        <origin xyz="0 0 0.02" rpy="0 0 0"/>
    </joint>

    <!-- Battery -->
    <link name="battery_link">
        <visual>
            <origin xyz="0 0 0" rpy="0 0 0"/>
            <geometry>
                <box size="0.06 0.04 0.02"/>
            </geometry>
            <material name="black"/>
        </visual>
        <collision>
            <origin xyz="0 0 0" rpy="0 0 0"/>
            <geometry>
                <box size="0.06 0.04 0.02"/>
            </geometry>
        </collision>
        <inertial>
            <origin xyz="0 0 0" rpy="0 0 0"/>
            <mass value="0.3"/>
            <inertia ixx="0.000075" ixy="0" ixz="0" iyy="0.000075" iyz="0" izz="0.00012"/>
        </inertial>
    </link>

    <joint name="battery_joint" type="fixed">
        <parent link="base_link"/>
        <child link="battery_link"/>
        <origin xyz="0 0 -0.03" rpy="0 0 0"/>
    </joint>
</robot>