<?xml version="1.0"?>
<robot name="Self_Balancing_Robot">
  <!-- Chassis -->
  <link name="Chassis">
    <visual>
      <geometry>
        <mesh filename="meshes/Robot_Body.stl" scale="0.001 0.001 0.001"/>
      </geometry>
      <origin xyz="0 0 0" rpy="0 0 1.5708"/> 
    </visual>
    <collision>
      <geometry>
        <mesh filename="meshes/Robot_Body.stl" scale="0.001 0.001 0.001"/>
      </geometry>
      <origin xyz="0 0 0" rpy="0 0 1.5708"/> 
    </collision>
    <inertial>
      <origin xyz="0 0 0.075" rpy="0 0 1.5708"/>
      <mass value="0.498"/>
      <inertia ixx="1.588" ixy="0" ixz="0" iyy="1.388" iyz="0" izz="2.178"/>
    </inertial>
  </link>

  <!-- Left Wheel -->
  <link name="Left_Wheel">
    <visual>
      <geometry>
        <mesh filename="meshes/Wheel.stl" scale="0.001 0.001 0.001" />
      </geometry>
      <origin xyz="0 -0.061 0.00" rpy="0 0 1.5708"/> 
    </visual>
    <collision>
      <geometry>
        <mesh filename="meshes/Wheel.stl" scale="0.001 0.001 0.001" />  
      </geometry>
      <origin xyz="0 -0.061 0.00" rpy="0 0 1.5708"/> 
    </collision>
    <inertial>
      <origin xyz="0 -0.061 0.00" rpy="0 0 1.5708"/>
      <mass value="0.015"/>
      <inertia ixx="0.0075" ixy="0" ixz="0" iyy="0.0001" iyz="0" izz="0.0000275"/>
    </inertial>
  </link>

  <!-- Right Wheel -->
  <link name="Right_Wheel">
    <visual>
      <geometry>
        <mesh filename="meshes/Wheel.stl" scale="0.001 0.001 0.001"/>
      </geometry>
      <origin xyz="0 0.061 0.00" rpy="0 0 -1.5708"/>  
    </visual>
    <collision>
      <geometry>
        <mesh filename="meshes/Wheel.stl" scale="0.001 0.001 0.001" />  
      </geometry>
      <origin xyz="0 0.061 0.00" rpy="0 0 -1.5708"/> 
    </collision>
    <inertial>
      <origin xyz="0 0.061 0.00" rpy="0 0 -1.5708"/>
      <mass value="0.015"/>
      <inertia ixx="0.0075" ixy="0" ixz="0" iyy="0.0001" iyz="0" izz="0.0000275"/>
    </inertial>
  </link>

  <!-- Left Wheel Joint -->
  <joint name="left_wheel_joint" type="continuous">
    <parent link="Chassis"/>
    <child link="Left_Wheel"/>
    <origin xyz="0 0.0 0.022" rpy="0 0 0"/>
    <limit effort="0.07" velocity="40"/>
    <axis xyz="0 1 0"/>
  </joint>

  <!-- Right Wheel Joint -->
  <joint name="right_wheel_joint" type="continuous">
    <parent link="Chassis"/>
    <child link="Right_Wheel"/>
    <origin xyz="0 0.00 0.022" rpy="0 0 0"/>
    <limit effort="0.07" velocity="40"/>
    <axis xyz="0 1 0"/>
  </joint>

</robot>
