<mujoco model="Self_Balancing_Robot">
    <asset>
        <mesh name="Robot_Body" file="Robot_Body.stl"/>
        <mesh name="Wheel" file="Wheel.stl"/>
    </asset>
  <!-- Chassis -->
  <worldbody>
      <body name="Chassis" pos="0 0 0.0215">
      <geom name="Chassis" type="mesh" mesh="Robot_Body"  rgba="0.75 0.75 0.75 1"/>
      <inertial pos="0 0 0.04" mass="0.478" diaginertia="0.478 0.0013 0.00"/>
      <!-- Left Wheel -->
      <body name="Left_Wheel" pos="0 0.061 0.00">
        <joint name="left_wheel_joint" type="hinge" pos="0 0 0" axis="0 1 0" limited="false"/>
        <geom type="mesh" mesh="Wheel" rgba="1 0 0 1"/>
        <inertial pos="0 0 0" mass="0.015" diaginertia="0.00 0.000 0.00"/>
      </body>
      <!-- Right Wheel -->
      <body name="Right_Wheel" pos="0 -0.061 0.00">
        <joint name="right_wheel_joint" type="hinge" pos="0 0 0" axis="0 1 0" limited="false"/>
        <geom type="mesh" mesh="Wheel"  rgba="1 1 1 1"/>
        <inertial pos="0 0 0" mass="0.015" diaginertia="0.00 0.00 0.00"/>
      </body>
    </body>
  </worldbody>
</mujoco>
