<?xml version="1.0"?>
<robot name="starship">
  <!-- Badan utama: silinder dengan diameter 0.1 m dan tinggi 1.0 m, massa 3 kg -->
  <link name="body">
    <inertial>
      <origin xyz="0 0 0" />
      <mass value="3.0"/>
      <!-- Inersia kasar: perhitungan untuk silinder (r=0.05, h=1.0) -->
      <inertia ixx="0.25" ixy="0" ixz="0" iyy="0.25" iyz="0" izz="0.00375"/>
    </inertial>
    <visual>
      <origin xyz="0 0 0" rpy="0 0 0"/>
      <geometry>
         <cylinder radius="0.05" length="1.0"/>
      </geometry>
      <material name="white">
         <color rgba="0.9 0.9 0.9 1"/>
      </material>
    </visual>
    <collision>
      <origin xyz="0 0 0" rpy="0 0 0"/>
      <geometry>
         <cylinder radius="0.05" length="1.0"/>
      </geometry>
    </collision>
  </link>

  <!-- Gimbal untuk thruster utama (rotasi terhadap sumbu Y) -->
  <link name="gimbal_y_frame">
    <inertial>
      <origin xyz="0 0 0"/>
      <mass value="0.001"/>
      <inertia ixx="0.0001" ixy="0" ixz="0" iyy="0.0001" iyz="0" izz="0.0001"/>
    </inertial>
  </link>
  <joint name="gimbal_y" type="revolute">
    <parent link="body"/>
    <child link="gimbal_y_frame"/>
    <!-- Pasang di bagian bawah body (z = -0.5) -->
    <origin xyz="0 0 -0.5" rpy="0 0 0"/>
    <axis xyz="0 1 0"/>
    <limit lower="-0.5" upper="0.5" effort="10" velocity="1.0"/>
  </joint>

  <!-- Gimbal kedua untuk thruster utama (rotasi terhadap sumbu X) -->
  <joint name="gimbal_x" type="revolute">
    <parent link="gimbal_y_frame"/>
    <child link="thruster"/>
    <origin xyz="0 0 0" rpy="0 0 0"/>
    <axis xyz="1 0 0"/>
    <limit lower="-0.5" upper="0.5" effort="10" velocity="1.0"/>
  </joint>

  <!-- Thruster Utama: silinder kecil, massa 1 kg -->
  <link name="thruster">
    <inertial>
      <!-- Pusat massa di tengah (origin diatur ke (0,0,-0.025)) -->
      <origin xyz="0 0 -0.025"/>
      <mass value="1.0"/>
      <!-- Perhitungan inersia kasar untuk silinder (r=0.03, length=0.05) -->
      <inertia ixx="0.000433" ixy="0" ixz="0" iyy="0.000433" iyz="0" izz="0.00045"/>
    </inertial>
    <visual>
      <origin xyz="0 0 -0.025" rpy="0 0 0"/>
      <geometry>
        <cylinder radius="0.03" length="0.05"/>
      </geometry>
      <material name="red">
        <color rgba="1 0 0 1"/>
      </material>
    </visual>
    <collision>
      <origin xyz="0 0 -0.025" rpy="0 0 0"/>
      <geometry>
        <cylinder radius="0.03" length="0.05"/>
      </geometry>
    </collision>
  </link>

  <!-- Tiga kaki landing berbentuk silinder (panjang 0.1 m, diameter 0.01 m) -->
  <!-- Leg 1 (sudut 0°) -->
  <joint name="leg_1_joint" type="fixed">
    <parent link="body"/>
    <!-- Ditempatkan 5.5 cm dari pusat, pada z = -0.5 (bawah badan) -->
    <origin xyz="0.055 0 -0.5" rpy="0 0 0"/>
    <child link="leg_1"/>
  </joint>
  <link name="leg_1">
    <inertial>
      <!-- Geser pusat massa ke tengah kaki (0,0,-0.05) -->
      <origin xyz="0 0 0"/>
      <mass value="0.32"/>
      <inertia ixx="0.00027" ixy="0" ixz="0" iyy="0.00027" iyz="0" izz="0.000004"/>
    </inertial>
    <visual>
      <origin xyz="0 0 0" rpy="0 0 0"/>
      <geometry>
        <cylinder radius="0.005" length="0.1"/>
      </geometry>
      <material name="blue">
        <color rgba="0 0 1 1"/>
      </material>
    </visual>
    <collision>
      <origin xyz="0 0 0" rpy="0 0 0"/>
      <geometry>
        <cylinder radius="0.005" length="0.1"/>
      </geometry>
    </collision>
  </link>
  <!-- Sensor pada ujung kaki 1 -->
  <joint name="leg_1_sensor_joint" type="fixed">
    <parent link="leg_1"/>
    <origin xyz="0 0 -0.05" rpy="0 0 0"/>
    <child link="leg_1_sensor"/>
  </joint>
  <link name="leg_1_sensor">
    <inertial>
      <origin xyz="0 0 0"/>
      <mass value="0.01"/>
      <inertia ixx="0.000001" ixy="0" ixz="0" iyy="0.000001" iyz="0" izz="0.000001"/>
    </inertial>
    <visual>
      <origin xyz="0 0 0" rpy="0 0 0"/>
      <geometry>
        <sphere radius="0.005"/>
      </geometry>
      <material name="green">
        <color rgba="0 1 0 1"/>
      </material>
    </visual>
    <collision>
      <origin xyz="0 0 0" rpy="0 0 0"/>
      <geometry>
        <sphere radius="0.005"/>
      </geometry>
    </collision>
  </link>

  <!-- Leg 2 (sudut 120°) -->
  <joint name="leg_2_joint" type="fixed">
    <parent link="body"/>
    <!-- Hitung posisi: cos(120°) = -0.5, sin(120°) ≈ 0.866 -->
    <origin xyz="-0.0275 0.0476 -0.5" rpy="0 0 0"/>
    <child link="leg_2"/>
  </joint>
  <link name="leg_2">
    <inertial>
      <origin xyz="0 0 0"/>
      <mass value="0.32"/>
      <inertia ixx="0.00027" ixy="0" ixz="0" iyy="0.00027" iyz="0" izz="0.000004"/>
    </inertial>
    <visual>
      <origin xyz="0 0 0" rpy="0 0 0"/>
      <geometry>
        <cylinder radius="0.005" length="0.1"/>
      </geometry>
      <material name="blue">
        <color rgba="0 0 1 1"/>
      </material>
    </visual>
    <collision>
      <origin xyz="0 0 0" rpy="0 0 0"/>
      <geometry>
        <cylinder radius="0.005" length="0.1"/>
      </geometry>
    </collision>
  </link>
  <!-- Sensor pada ujung kaki 2 -->
  <joint name="leg_2_sensor_joint" type="fixed">
    <parent link="leg_2"/>
    <origin xyz="0 0 -0.05" rpy="0 0 0"/>
    <child link="leg_2_sensor"/>
  </joint>
  <link name="leg_2_sensor">
    <inertial>
      <origin xyz="0 0 0"/>
      <mass value="0.01"/>
      <inertia ixx="0.000001" ixy="0" ixz="0" iyy="0.000001" iyz="0" izz="0.000001"/>
    </inertial>
    <visual>
      <origin xyz="0 0 0" rpy="0 0 0"/>
      <geometry>
        <sphere radius="0.005"/>
      </geometry>
      <material name="green">
        <color rgba="0 1 0 1"/>
      </material>
    </visual>
    <collision>
      <origin xyz="0 0 0" rpy="0 0 0"/>
      <geometry>
        <sphere radius="0.005"/>
      </geometry>
    </collision>
  </link>

  <!-- Leg 3 (sudut 240°) -->
  <joint name="leg_3_joint" type="fixed">
    <parent link="body"/>
    <!-- Hitung posisi: cos(240°) = -0.5, sin(240°) ≈ -0.866 -->
    <origin xyz="-0.0275 -0.0476 -0.5" rpy="0 0 0"/>
    <child link="leg_3"/>
  </joint>
  <link name="leg_3">
    <inertial>
      <origin xyz="0 0 0"/>
      <mass value="0.32"/>
      <inertia ixx="0.00027" ixy="0" ixz="0" iyy="0.00027" iyz="0" izz="0.000004"/>
    </inertial>
    <visual>
      <origin xyz="0 0 0" rpy="0 0 0"/>
      <geometry>
        <cylinder radius="0.005" length="0.1"/>
      </geometry>
      <material name="blue">
        <color rgba="0 0 1 1"/>
      </material>
    </visual>
    <collision>
      <origin xyz="0 0 0" rpy="0 0 0"/>
      <geometry>
        <cylinder radius="0.005" length="0.1"/>
      </geometry>
    </collision>
  </link>
  <!-- Sensor pada ujung kaki 3 -->
  <joint name="leg_3_sensor_joint" type="fixed">
    <parent link="leg_3"/>
    <origin xyz="0 0 -0.05" rpy="0 0 0"/>
    <child link="leg_3_sensor"/>
  </joint>
  <link name="leg_3_sensor">
    <inertial>
      <origin xyz="0 0 0"/>
      <mass value="0.01"/>
      <inertia ixx="0.000001" ixy="0" ixz="0" iyy="0.000001" iyz="0" izz="0.000001"/>
    </inertial>
    <visual>
      <origin xyz="0 0 0" rpy="0 0 0"/>
      <geometry>
        <sphere radius="0.005"/>
      </geometry>
      <material name="green">
        <color rgba="0 1 0 1"/>
      </material>
    </visual>
    <collision>
      <origin xyz="0 0 0" rpy="0 0 0"/>
      <geometry>
        <sphere radius="0.005"/>
      </geometry>
    </collision>
  </link>
</robot>
